{"uuid": "9c6c6a00-7090-4970-893d-077254fb3195", "children": ["a901a098-4eb2-4198-a2e1-07bac1cc8f8f", "52eb0c00-92c8-45e7-926d-64c19863c06d"], "befores": [{"name": "test_setup", "status": "broken", "statusDetails": {"message": "selenium.common.exceptions.WebDriverException: Message: 'chromedriver.exe' executable needs to be in PATH. Please see https://sites.google.com/a/chromium.org/chromedriver/home\n\n", "trace": "  File \"C:\\Program Files (x86)\\Python\\lib\\site-packages\\pluggy\\callers.py\", line 180, in _multicall\n    res = hook_impl.function(*args)\n  File \"C:\\Program Files (x86)\\Python\\lib\\site-packages\\_pytest\\fixtures.py\", line 938, in pytest_fixture_setup\n    result = call_fixture_func(fixturefunc, request, kwargs)\n  File \"C:\\Program Files (x86)\\Python\\lib\\site-packages\\_pytest\\fixtures.py\", line 795, in call_fixture_func\n    res = next(it)\n  File \"C:\\Users\\Administrator\\PycharmProjects\\AutomationFramework_1\\conftest.py\", line 15, in test_setup\n    executable_path=\"C:/Users/Administrator/PycharmProjects/AutomationFramework_1/driver/chromedriver.exe\")\n  File \"C:\\Program Files (x86)\\Python\\lib\\site-packages\\selenium\\webdriver\\chrome\\webdriver.py\", line 68, in __init__\n    self.service.start()\n  File \"C:\\Program Files (x86)\\Python\\lib\\site-packages\\selenium\\webdriver\\common\\service.py\", line 83, in start\n    os.path.basename(self.path), self.start_error_message)\n"}, "start": 1539242414972, "stop": 1539242414973}], "start": 1539242414972, "stop": 1539242415270}